<robot name='robot'>
	<material name='blue'>
		<color rgba='0 0 0.8 1'/>
	</material>
	<material name='red'>
		<color rgba='0.8 0 0 1'/>
	</material>
	<link name='a0'>
		<visual>
			<origin rpy='-0.0 0.0 0.0' xyz='0.0 0.0 0.0'/>
			<geometry>
				<cylinder length='0.1' radius='0.05'/>
			</geometry>
			<material name='blue'><color rgba='0.73 0.79 0.82 1'/></material>
		</visual>
	</link>
	<link name='l0'>
		<visual>
			<origin rpy='-0.0 0.0 0.0' xyz='0.0 0.0 0.1'/>
			<geometry>
				<cylinder length='0.2' radius='0.04'/>
			</geometry>
			<material name='grey'><color rgba='0.99 0.54 0.54 1'/></material>
		</visual>
	</link>
	<joint name='move_l0_from_a0' type='continuous'>
		<parent link='a0'/>
		<child link='l0'/>
		<axis xyz='0.0 0.0 1.0'/>
		<origin rpy='0 0 0' xyz='0.0 0.0 0.0'/>
	</joint>
	<link name='a1'>
		<visual>
			<origin rpy='1.5707963267948966 0.0 0.0' xyz='0.0 0.0 0.2'/>
			<geometry>
				<cylinder length='0.1' radius='0.05'/>
			</geometry>
			<material name='blue'><color rgba='0.73 0.79 0.82 1'/></material>
		</visual>
	</link>
	<joint name='fix_a1_to_l0' type='fixed'>
		<parent link='l0'/>
		<child link='a1'/>
		<origin rpy='0 0 0' xyz='0 0 0'/>
	</joint>
	<link name='l1'>
		<visual>
			<origin rpy='-0.0 1.5707963267948966 0.0' xyz='0.15 0.0 0.0'/>
			<geometry>
				<cylinder length='0.3' radius='0.04'/>
			</geometry>
			<material name='grey'><color rgba='0.99 0.54 0.54 1'/></material>
		</visual>
	</link>
	<joint name='move_l1_from_a1' type='continuous'>
		<parent link='a1'/>
		<child link='l1'/>
		<axis xyz='0.0 -1.0 0.0'/>
		<origin rpy='0 0 0' xyz='0.0 0.0 0.2'/>
	</joint>
	<link name='a2'>
		<visual>
			<origin rpy='1.5707963267948966 0.0 0.0' xyz='0.3 0.0 0.0'/>
			<geometry>
				<cylinder length='0.1' radius='0.05'/>
			</geometry>
			<material name='blue'><color rgba='0.73 0.79 0.82 1'/></material>
		</visual>
	</link>
	<joint name='fix_a2_to_l1' type='fixed'>
		<parent link='l1'/>
		<child link='a2'/>
		<origin rpy='0 0 0' xyz='0 0 0'/>
	</joint>
	<link name='l2'>
		<visual>
			<origin rpy='-0.0 1.5707963267948966 0.0' xyz='0.15 0.0 0.0'/>
			<geometry>
				<cylinder length='0.3' radius='0.04'/>
			</geometry>
			<material name='grey'><color rgba='0.99 0.54 0.54 1'/></material>
		</visual>
	</link>
	<joint name='move_l2_from_a2' type='continuous'>
		<parent link='a2'/>
		<child link='l2'/>
		<axis xyz='0.0 -1.0 0.0'/>
		<origin rpy='0 0 0' xyz='0.3 0.0 0.0'/>
	</joint>
</robot>
