<robot name='robot'>
	<material name='blue'>
		<color rgba='0 0 0.8 1'/>
	</material>
	<material name='red'>
		<color rgba='0.8 0 0 1'/>
	</material>
	<link name='a0'>
		<visual>
			<origin rpy='-0.0 0.0 0.0' xyz='0.0 0.0 0.0'/>
			<geometry>
				<cylinder length='1' radius='0.5'/>
			</geometry>
			<material name='blue'><color rgba='0 0 0.8 1'/></material>
		</visual>
	</link>
	<link name='l0'>
		<visual>
			<origin rpy='-0.0 0.0 0.0' xyz='0.0 0.0 1.2'/>
			<geometry>
				<cylinder length='2.4' radius='0.4'/>
			</geometry>
			<material name='red'><color rgba='0.8 0 0 1'/></material>
		</visual>
	</link>
	<joint name='move_l0_from_a0' type='continuous'>
		<parent link='a0'/>
		<child link='l0'/>
		<axis xyz='0.0 0.0 1.0'/>
		<origin rpy='0 0 0' xyz='0.0 0.0 0.0'/>
	</joint>
	<link name='a1'>
		<visual>
			<origin rpy='1.5707963267948966 0.0 0.0' xyz='0.0 0.0 2.4'/>
			<geometry>
				<cylinder length='1' radius='0.5'/>
			</geometry>
			<material name='blue'><color rgba='0 0 0.8 1'/></material>
		</visual>
	</link>
	<joint name='fix_a1_to_l0' type='fixed'>
		<parent link='l0'/>
		<child link='a1'/>
		<origin rpy='0 0 0' xyz='0 0 0'/>
	</joint>
	<link name='l1'>
		<visual>
			<origin rpy='-0.0 -1.5707963267948963 0.0' xyz='-1.2 -0.0 0.0'/>
			<geometry>
				<cylinder length='2.4' radius='0.4'/>
			</geometry>
			<material name='red'><color rgba='0.8 0 0 1'/></material>
		</visual>
	</link>
	<joint name='move_l1_from_a1' type='continuous'>
		<parent link='a1'/>
		<child link='l1'/>
		<axis xyz='0.0 -1.0 6.123233995736766e-17'/>
		<origin rpy='0 0 0' xyz='0.0 0.0 2.4'/>
	</joint>
	<link name='a2'>
		<visual>
			<origin rpy='1.5707963267948966 0.0 0.0' xyz='-2.4 -0.0 0.0'/>
			<geometry>
				<cylinder length='1' radius='0.5'/>
			</geometry>
			<material name='blue'><color rgba='0 0 0.8 1'/></material>
		</visual>
	</link>
	<joint name='fix_a2_to_l1' type='fixed'>
		<parent link='l1'/>
		<child link='a2'/>
		<origin rpy='0 0 0' xyz='0 0 0'/>
	</joint>
	<link name='l2'>
		<visual>
			<origin rpy='-0.0 -1.5707963267948963 0.0' xyz='-1.2 -0.0 0.0'/>
			<geometry>
				<cylinder length='2.4' radius='0.4'/>
			</geometry>
			<material name='red'><color rgba='0.8 0 0 1'/></material>
		</visual>
	</link>
	<joint name='move_l2_from_a2' type='continuous'>
		<parent link='a2'/>
		<child link='l2'/>
		<axis xyz='0.0 -1.0 6.123233995736766e-17'/>
		<origin rpy='0 0 0' xyz='-2.4 -0.0 0.0'/>
	</joint>
	<link name='a3'>
		<visual>
			<origin rpy='1.5707963267948966 0.0 0.0' xyz='-2.4 -0.0 0.0'/>
			<geometry>
				<cylinder length='1' radius='0.5'/>
			</geometry>
			<material name='blue'><color rgba='0 0 0.8 1'/></material>
		</visual>
	</link>
	<joint name='fix_a3_to_l2' type='fixed'>
		<parent link='l2'/>
		<child link='a3'/>
		<origin rpy='0 0 0' xyz='0 0 0'/>
	</joint>
	<link name='l3'>
		<visual>
			<origin rpy='-0.0 -1.5707963267948963 0.0' xyz='-1.2 -0.0 0.0'/>
			<geometry>
				<cylinder length='2.4' radius='0.4'/>
			</geometry>
			<material name='red'><color rgba='0.8 0 0 1'/></material>
		</visual>
	</link>
	<joint name='move_l3_from_a3' type='continuous'>
		<parent link='a3'/>
		<child link='l3'/>
		<axis xyz='0.0 -1.0 6.123233995736766e-17'/>
		<origin rpy='0 0 0' xyz='-2.4 -0.0 0.0'/>
	</joint>
</robot>
